Workbook

Sheet Down regulating DEGs
A1: Gene_id | B1: readcount_ND2 | C1: readcount_LUC | D1: log2FoldChange | E1: pval | F1: padj | G1: Associated Gene Name | H1: gene_biotype | I1: Description
A2: ENSG00000000003 | B2: 464.82906 | C2: 626.74201 | D2: -0.43117 | E2: 4.5378e-06 | F2: 8.0254e-05 | G2: TSPAN6 | H2: protein_coding | I2: tetraspanin 6 [Source:HGNC Symbol;Acc:HGNC:11858]
A3: ENSG00000001084 | B3: 2282.4884 | C3: 2933.1273 | D3: -0.36183 | E3: 2.9091e-12 | F3: 1.2528e-10 | G3: GCLC | H3: protein_coding | I3: glutamate-cysteine ligase, catalytic subunit [Source:HGNC Symbol;Acc:HGNC:4311]
A4: ENSG00000001461 | B4: 344.3264 | C4: 451.54982 | D4: -0.39111 | E4: 0.00027243 | F4: 0.0032539 | G4: NIPAL3 | H4: protein_coding | I4: NIPA-like domain containing 3 [Source:HGNC Symbol;Acc:HGNC:25233]
A5: ENSG00000003436 | B5: 711.9742 | C5: 898.7152 | D5: -0.33604 | E5: 0.00023429 | F5: 0.0028393 | G5: TFPI | H5: protein_coding | I5: tissue factor pathway inhibitor [Source:HGNC Symbol;Acc:HGNC:11760]
A6: ENSG00000003756 | B6: 803.86518 | C6: 972.32103 | D6: -0.27448 | E6: 0.00032075 | F6: 0.0037469 | G6: RBM5 | H6: protein_coding | I6: RNA binding motif protein 5 [Source:HGNC Symbol;Acc:HGNC:9902]
A7: ENSG00000004487 | B7: 1548.6567 | C7: 1744.1543 | D7: -0.17151 | E7: 0.0044984 | F7: 0.037268 | G7: KDM1A | H7: protein_coding | I7: lysine (K)-specific demethylase 1A [Source:HGNC Symbol;Acc:HGNC:29079]
A8: ENSG00000004534 | B8: 997.9561 | C8: 1223.9487 | D8: -0.29449 | E8: 2.4216e-05 | F8: 0.00037103 | G8: RBM6 | H8: protein_coding | I8: RNA binding motif protein 6 [Source:HGNC Symbol;Acc:HGNC:9903]
A9: ENSG00000004864 | B9: 410.71571 | C9: 519.91599 | D9: -0.34014 | E9: 0.00073039 | F9: 0.0077541 | G9: SLC25A13 | H9: protein_coding | I9: solute carrier family 25 (aspartate/glutamate carrier), member 13 [Source:HGNC Symbol;Acc:HGNC:10983]
A10: ENSG00000005156 | B10: 514.63289 | C10: 624.48167 | D10: -0.27912 | E10: 0.0022132 | F10: 0.020406 | G10: LIG3 | H10: protein_coding | I10: ligase III, DNA, ATP-dependent [Source:HGNC Symbol;Acc:HGNC:6600]
A11: ENSG00000005189 | B11: 126.96513 | C11: 176.88684 | D11: -0.47839 | E11: 0.0045713 | F11: 0.037777 | G11: AC004381.6 | H11: protein_coding | I11: Putative RNA exonuclease NEF-sp [Source:UniProtKB/Swiss-Prot;Acc:Q96IC2]
A12: ENSG00000005194 | B12: 612.73477 | C12: 730.56803 | D12: -0.25376 | E12: 0.0029458 | F12: 0.026041 | G12: CIAPIN1 | H12: protein_coding | I12: cytokine induced apoptosis inhibitor 1 [Source:HGNC Symbol;Acc:HGNC:28050]
A13: ENSG00000005483 | B13: 748.36452 | C13: 1146.613 | D13: -0.61557 | E13: 8.891e-15 | F13: 5.0086e-13 | G13: KMT2E | H13: protein_coding | I13: lysine (K)-specific methyltransferase 2E [Source:HGNC Symbol;Acc:HGNC:18541]
... A311: ENSG00000100097 | B311: 4779.157 | C311: 6606.5526 | D311: -0.46714 | E311: 1.0503e-27 | F311: 1.4764e-25 | G311: LGALS1 | H311: protein_coding | I311: lectin, galactoside-binding, soluble, 1 [Source:HGNC Symbol;Acc:HGNC:6561]
A312: ENSG00000100167 | B312: 104.90342 | C312: 272.21286 | D312: -1.3757 | E312: 2.3813e-18 | F312: 1.7565e-16 | G312: 44807 | H312: protein_coding | I312: septin 3 [Source:HGNC Symbol;Acc:HGNC:10750]
A313: ENSG00000100196 | B313: 117.245 | C313: 176.10703 | D313: -0.58693 | E313: 0.00078356 | F313: 0.0082469 | G313: KDELR3 | H313: protein_coding | I313: KDEL endoplasmic reticulum protein retention receptor 3 [Source:HGNC Symbol;Acc:HGNC:6306]
A314: ENSG00000100219 | B314: 609.00495 | C314: 747.41839 | D314: -0.29546 | E314: 0.00058832 | F314: 0.0064149 | G314: XBP1 | H314: protein_coding | I314: X-box binding protein 1 [Source:HGNC Symbol;Acc:HGNC:12801]
A315: ENSG00000100311 | B315: 202.33991 | C315: 279.4878 | D315: -0.466 | E315: 0.002821 | F315: 0.02514 | G315: PDGFB | H315: protein_coding | I315: platelet-derived growth factor beta polypeptide [Source:HGNC Symbol;Acc:HGNC:8800]
A316: ENSG00000100320 | B316: 1022.5991 | C316: 1579.7869 | D316: -0.62749 | E316: 1.2384e-21 | F316: 1.1943e-19 | G316: RBFOX2 | H316: protein_coding | I316: RNA binding protein, fox-1 homolog (C. elegans) 2 [Source:HGNC Symbol;Acc:HGNC:9906]
A317: ENSG00000100354 | B317: 526.02288 | C317: 769.40379 | D317: -0.54862 | E317: 3.4266e-10 | F317: 1.1604e-08 | G317: TNRC6B | H317: protein_coding | I317: trinucleotide repeat containing 6B [Source:HGNC Symbol;Acc:HGNC:29190]
A318: ENSG00000100387 | B318: 410.70477 | C318: 580.44153 | D318: -0.49905 | E318: 3.7394e-07 | F318: 8.0516e-06 | G318: RBX1 | H318: protein_coding | I318: ring-box 1, E3 ubiquitin protein ligase [Source:HGNC Symbol;Acc:HGNC:9928]
A319: ENSG00000100425 | B319: 332.10149 | C319: 431.32476 | D319: -0.37715 | E319: 0.00060508 | F319: 0.0065581 | G319: BRD1 | H319: protein_coding | I319: bromodomain containing 1 [Source:HGNC Symbol;Acc:HGNC:1102]
A320: ENSG00000100439 | B320: 311.59843 | C320: 429.82476 | D320: -0.46406 | E320: 3.2076e-05 | F320: 0.00047791 | G320: ABHD4 | H320: protein_coding | I320: abhydrolase domain containing 4 [Source:HGNC Symbol;Acc:HGNC:20154]
A321: ENSG00000100504 | B321: 777.40278 | C321: 931.67019 | D321: -0.26116 | E321: 0.00077758 | F321: 0.0081937 | G321: PYGL | H321: protein_coding | I321: phosphorylase, glycogen, liver [Source:HGNC Symbol;Acc:HGNC:9725]
A322: ENSG00000100526 | B322: 388.59019 | C322: 477.98047 | D322: -0.2987 | E322: 0.004368 | F322: 0.036381 | G322: CDKN3 | H322: protein_coding | I322: cyclin-dependent kinase inhibitor 3 [Source:HGNC Symbol;Acc:HGNC:1791]
A323: ENSG00000100528 | B323: 609.32579 | C323: 906.6848 | D323: -0.57339 | E323: 1.8116e-12 | F323: 8.0097e-11 | G323: CNIH1 | H323: protein_coding | I323: cornichon family AMPA receptor auxiliary protein 1 [Source:HGNC Symbol;Acc:HGNC:19431]
A324: ENSG00000100554 | B324: 366.56312 | C324: 450.81502 | D324: -0.29847 | E324: 0.0051009 | F324: 0.041419 | G324: ATP6V1D | H324: protein_coding | I324: ATPase, H+ transporting, lysosomal 34kDa, V1 subunit D [Source:HGNC Symbol;Acc:HGNC:13527]
... A712: ENSG00000122482 | B712: 502.15095 | C712: 604.67145 | D712: -0.26803 | E712: 0.0035815 | F712: 0.030607 | G712: ZNF644 | H712: protein_coding | I712: zinc finger protein 644 [Source:HGNC Symbol;Acc:HGNC:29222]
A713: ENSG00000122545 | B713: 1111.2197 | C713: 2130.1542 | D713: -0.93881 | E713: 9.2349e-53 | F713: 4.9143e-50 | G713: 44811 | H713: protein_coding | I713: septin 7 [Source:HGNC Symbol;Acc:HGNC:1717]
A714: ENSG00000122565 | B714: 1980.0267 | C714: 3359.0823 | D714: -0.76255 | E714: 6.8832e-49 | F714: 3.205e-46 | G714: CBX3 | H714: protein_coding | I714: chromobox 3 [Source:HGNC Symbol;Acc:HGNC:1553]
A715: ENSG00000122591 | B715: 450.25069 | C715: 689.91232 | D715: -0.61568 | E715: 1.5858e-11 | F715: 6.3262e-10 | G715: FAM126A | H715: protein_coding | I715: family with sequence similarity 126 member A [Source:HGNC Symbol;Acc:HGNC:24587]
A716: ENSG00000122592 | B716: 24.251111 | C716: 58.475661 | D716: -1.2698 | E716: 0.00013894 | F716: 0.001777 | G716: HOXA7 | H716: protein_coding | I716: homeobox A7 [Source:HGNC Symbol;Acc:HGNC:5108]
A717: ENSG00000122705 | B717: 1119.4158 | C717: 1291.3989 | D717: -0.20619 | E717: 0.0019828 | F717: 0.018564 | G717: CLTA | H717: protein_coding | I717: clathrin, light chain A [Source:HGNC Symbol;Acc:HGNC:2090]
A718: ENSG00000122786 | B718: 2123.7542 | C718: 2796.2904 | D718: -0.3969 | E718: 5.5239e-14 | F718: 2.8678e-12 | G718: CALD1 | H718: protein_coding | I718: caldesmon 1 [Source:HGNC Symbol;Acc:HGNC:1441]
A719: ENSG00000122861 | B719: 1202.4508 | C719: 1700.2029 | D719: -0.49973 | E719: 3.8719e-11 | F719: 1.4717e-09 | G719: PLAU | H719: protein_coding | I719: plasminogen activator, urokinase [Source:HGNC Symbol;Acc:HGNC:9052]
A720: ENSG00000122862 | B720: 800.88825 | C720: 1008.4561 | D720: -0.33248 | E720: 1.0386e-05 | F720: 0.00017066 | G720: SRGN | H720: protein_coding | I720: serglycin [Source:HGNC Symbol;Acc:HGNC:9361]
A721: ENSG00000122873 | B721: 283.05055 | C721: 384.16418 | D721: -0.44066 | E721: 0.00016422 | F721: 0.0020554 | G721: CISD1 | H721: protein_coding | I721: CDGSH iron sulfur domain 1 [Source:HGNC Symbol;Acc:HGNC:30880]
A722: ENSG00000122884 | B722: 749.58957 | C722: 1052.4159 | D722: -0.48953 | E722: 6.7056e-07 | F722: 1.381e-05 | G722: P4HA1 | H722: protein_coding | I722: prolyl 4-hydroxylase, alpha polypeptide I [Source:HGNC Symbol;Acc:HGNC:8546]
A723: ENSG00000122966 | B723: 1178.2051 | C723: 1572.383 | D723: -0.41636 | E723: 1.1808e-10 | F723: 4.2447e-09 | G723: CIT | H723: protein_coding | I723: citron rho-interacting serine/threonine kinase [Source:HGNC Symbol;Acc:HGNC:1985]
A724: ENSG00000123094 | B724: 136.53943 | C724: 273.20313 | D724: -1.0007 | E724: 1.9528e-11 | F724: 7.7179e-10 | G724: RASSF8 | H724: protein_coding | I724: Ras association (RalGDS/AF-6) domain family (N-terminal) member 8 [Source:HGNC Symbol;Acc:HGNC:13232]
...

Sheet Up regulating DEGs
A1: Gene_id | B1: readcount_ND2 | C1: readcount_LUC | D1: log2FoldChange | E1: pval | F1: padj | G1: Associated Gene Name | H1: gene_biotype | I1: Description
A2: ENSG00000001036 | B2: 1504.7666 | C2: 1260.5838 | D2: 0.25545 | E2: 6.72e-05 | F2: 0.00093032 | G2: FUCA2 | H2: protein_coding | I2: fucosidase, alpha-L- 2, plasma [Source:HGNC Symbol;Acc:HGNC:4008]
A3: ENSG00000001497 | B3: 1098.1362 | C3: 902.54002 | D3: 0.28299 | E3: 9.76e-05 | F3: 0.0013007 | G3: LAS1L | H3: protein_coding | I3: LAS1-like, ribosome biogenesis factor [Source:HGNC Symbol;Acc:HGNC:25726]
A4: ENSG00000001626 | B4: 27.222571 | C4: 7.8600962 | D4: 1.7922 | E4: 0.0009204 | F4: 0.0095104 | G4: CFTR | H4: protein_coding | I4: cystic fibrosis transmembrane conductance regulator [Source:HGNC Symbol;Acc:HGNC:1884]
A5: ENSG00000002822 | B5: 472.85565 | C5: 356.76881 | D5: 0.40641 | E5: 0.00013966 | F5: 0.0017847 | G5: MAD1L1 | H5: protein_coding | I5: MAD1 mitotic arrest deficient-like 1 (yeast) [Source:HGNC Symbol;Acc:HGNC:6762]
A6: ENSG00000003056 | B6: 1260.819 | C6: 988.92566 | D6: 0.35043 | E6: 4.69e-07 | F6: 9.88e-06 | G6: M6PR | H6: protein_coding | I6: mannose-6-phosphate receptor (cation dependent) [Source:HGNC Symbol;Acc:HGNC:6752]
A7: ENSG00000004961 | B7: 326.42656 | C7: 250.80288 | D7: 0.3802 | E7: 0.0023309 | F7: 0.021339 | G7: HCCS | H7: protein_coding | I7: holocytochrome c synthase [Source:HGNC Symbol;Acc:HGNC:4837]
A8: ENSG00000004975 | B8: 1373.1948 | C8: 953.71034 | D8: 0.52591 | E8: 2.04e-14 | F8: 1.11e-12 | G8: DVL2 | H8: protein_coding | I8: dishevelled segment polarity protein 2 [Source:HGNC Symbol;Acc:HGNC:3086]
A9: ENSG00000005007 | B9: 1799.7394 | C9: 1426.2456 | D9: 0.33557 | E9: 1.23e-06 | F9: 2.41e-05 | G9: UPF1 | H9: protein_coding | I9: UPF1 regulator of nonsense transcripts homolog (yeast) [Source:HGNC Symbol;Acc:HGNC:9962]
A10: ENSG00000005100 | B10: 947.37568 | C10: 759.42326 | D10: 0.31903 | E10: 3.93e-05 | F10: 0.00057389 | G10: DHX33 | H10: protein_coding | I10: DEAH (Asp-Glu-Ala-His) box polypeptide 33 [Source:HGNC Symbol;Acc:HGNC:16718]
A11: ENSG00000005206 | B11: 341.87996 | C11: 266.02794 | D11: 0.36191 | E11: 0.0030881 | F11: 0.027143 | G11: SPPL2B | H11: protein_coding | I11: signal peptide peptidase like 2B [Source:HGNC Symbol;Acc:HGNC:30627]
A12: ENSG00000005243 | B12: 200.46041 | C12: 137.99147 | D12: 0.53874 | E12: 0.0024799 | F12: 0.022558 | G12: COPZ2 | H12: protein_coding | I12: coatomer protein complex subunit zeta 2 [Source:HGNC Symbol;Acc:HGNC:19356]
A13: ENSG00000005448 | B13: 712.15101 | C13: 590.54615 | D13: 0.27013 | E13: 0.0053953 | F13: 0.043477 | G13: WDR54 | H13: protein_coding | I13: WD repeat domain 54 [Source:HGNC Symbol;Acc:HGNC:25770]
... A1524: ENSG00000184428 | B1524: 368.72882 | C1524: 198.10703 | D1524: 0.89628 | E1524: 3.19e-12 | F1524: 1.37e-10 | G1524: TOP1MT | H1524: protein_coding | I1524: topoisomerase (DNA) I, mitochondrial [Source:HGNC Symbol;Acc:HGNC:29787]
A1525: ENSG00000184640 | B1525: 3676.3576 | C1525: 2710.7296 | D1525: 0.4396 | E1525: 3.55e-19 | F1525: 2.8e-17 | G1525: 44813 | H1525: protein_coding | I1525: septin 9 [Source:HGNC Symbol;Acc:HGNC:7323]
A1526: ENSG00000184840 | B1526: 2004.7209 | C1526: 1543.1762 | D1526: 0.3775 | E1526: 4.23e-07 | F1526: 9.02e-06 | G1526: TMED9 | H1526: protein_coding | I1526: transmembrane p24 trafficking protein 9 [Source:HGNC Symbol;Acc:HGNC:24878]
A1527: ENSG00000184857 | B1527: 197.7861 | C1527: 121.04621 | D1527: 0.70838 | E1527: 2.67e-05 | F1527: 0.00040483 | G1527: TMEM186 | H1527: protein_coding | I1527: transmembrane protein 186 [Source:HGNC Symbol;Acc:HGNC:24530]
A1528: ENSG00000184887 | B1528: 649.75951 | C1528: 533.3357 | D1528: 0.28486 | E1528: 0.0017352 | F1528: 0.016579 | G1528: BTBD6 | H1528: protein_coding | I1528: BTB (POZ) domain containing 6 [Source:HGNC Symbol;Acc:HGNC:19897]
A1529: ENSG00000184939 | B1529: 209.63183 | C1529: 154.2518 | D1529: 0.44257 | E1529: 0.0040198 | F1529: 0.033791 | G1529: ZFP90 | H1529: protein_coding | I1529: ZFP90 zinc finger protein [Source:HGNC Symbol;Acc:HGNC:23329]
A1530: ENSG00000184949 | B1530: 52.25027 | C1530: 25.990264 | D1530: 1.0075 | E1530: 0.0032855 | F1530: 0.028511 | G1530: FAM227A | H1530: protein_coding | I1530: family with sequence similarity 227 member A [Source:HGNC Symbol;Acc:HGNC:44197]
A1531: ENSG00000185009 | B1531: 589.03785 | C1531: 449.67025 | D1531: 0.38949 | E1531: 4.26e-05 | F1531: 0.00061689 | G1531: AP3M1 | H1531: protein_coding | I1531: adaptor related protein complex 3, mu 1 subunit [Source:HGNC Symbol;Acc:HGNC:569]
A1532: ENSG00000185019 | B1532: 145.99705 | C1532: 94.186118 | D1532: 0.63235 | E1532: 0.00091842 | F1532: 0.0094932 | G1532: UBOX5 | H1532: protein_coding | I1532: U-box domain containing 5 [Source:HGNC Symbol;Acc:HGNC:17777]
A1533: ENSG00000185043 | B1533: 568.44181 | C1533: 450.49507 | D1533: 0.3355 | E1533: 0.00047956 | F1533: 0.0053444 | G1533: CIB1 | H1533: protein_coding | I1533: calcium and integrin binding 1 [Source:HGNC Symbol;Acc:HGNC:16920]
A1534: ENSG00000185049 | B1534: 604.947 | C1534: 435.19459 | D1534: 0.47515 | E1534: 7.9e-07 | F1534: 1.6e-05 | G1534: NELFA | H1534: protein_coding | I1534: negative elongation factor complex member A [Source:HGNC Symbol;Acc:HGNC:12768]
A1535: ENSG00000185122 | B1535: 1042.8798 | C1535: 822.89405 | D1535: 0.34179 | E1535: 4.7e-06 | F1535: 8.3e-05 | G1535: HSF1 | H1535: protein_coding | I1535: heat shock transcription factor 1 [Source:HGNC Symbol;Acc:HGNC:5224]
A1536: ENSG00000185189 | B1536: 182.93428 | C1536: 118.22626 | D1536: 0.62977 | E1536: 0.00025266 | F1536: 0.0030445 | G1536: NRBP2 | H1536: protein_coding | I1536: nuclear receptor binding protein 2 [Source:HGNC Symbol;Acc:HGNC:19339]
A1537: ENSG00000185215 | B1537: 1154.7306 | C1537: 999.24075 | D1537: 0.20865 | E1537: 0.0032289 | F1537: 0.028124 | G1537: TNFAIP2 | H1537: protein_coding | I1537: TNF alpha induced protein 2 [Source:HGNC Symbol;Acc:HGNC:11895]
... A1761: ENSG00000231721 | B1761: 178.1763 | C1761: 101.27127 | D1761: 0.81508 | E1761: 4.14e-06 | F1761: 7.37e-05 | G1761: LINC-PINT | H1761: antisense | I1761: long intergenic non-protein coding RNA, p53 induced transcript [Source:HGNC Symbol;Acc:HGNC:26885]
A1762: ENSG00000231738 | B1762: 12.399914 | C1762: 0 | D1762: Inf | E1762: 4.34e-05 | F1762: 0.00062761 | G1762: TSPAN19 | H1762: protein_coding | I1762: tetraspanin 19 [Source:HGNC Symbol;Acc:HGNC:31886]
A1763: ENSG00000231789 | B1763: 122.61003 | C1763: 66.115565 | D1763: 0.89102 | E1763: 0.00018583 | F1763: 0.0023007 | G1763: PIK3CD-AS2 | H1763: antisense | I1763: PIK3CD antisense RNA 2 [Source:HGNC Symbol;Acc:HGNC:51334]
A1764: ENSG00000232098 | B1764: 235.26658 | C1764: 143.67151 | D1764: 0.71152 | E1764: 3.7e-06 | F1764: 6.67e-05 | G1764: CTD-2619J13.14 | H1764: lincRNA | I1764: -
A1765: ENSG00000233237 | B1765: 32.009718 | C1765: 12.040144 | D1765: 1.4107 | E1765: 0.0026628 | F1765: 0.024002 | G1765: LINC00472 | H1765: lincRNA | I1765: long intergenic non-protein coding RNA 472 [Source:HGNC Symbol;Acc:HGNC:21380]
A1766: ENSG00000234127 | B1766: 629.68302 | C1766: 435.01941 | D1766: 0.53355 | E1766: 1.88e-06 | F1766: 3.56e-05 | G1766: TRIM26 | H1766: protein_coding | I1766: tripartite motif containing 26 [Source:HGNC Symbol;Acc:HGNC:12962]
A1767: ENSG00000234171 | B1767: 194.21306 | C1767: 124.40631 | D1767: 0.64258 | E1767: 0.00013523 | F1767: 0.0017355 | G1767: RNASEH1-AS1 | H1767: antisense | I1767: RNASEH1 antisense RNA 1 [Source:HGNC Symbol;Acc:HGNC:49289]
A1768: ENSG00000234327 | B1768: 82.181788 | C1768: 46.615565 | D1768: 0.81801 | E1768: 0.0017343 | F1768: 0.016575 | G1768: AC012146.7 | H1768: processed_transcript | I1768: -
A1769: ENSG00000234608 | B1769: 248.97358 | C1769: 186.01214 | D1769: 0.4206 | E1769: 0.003307 | F1769: 0.028646 | G1769: MAPKAPK5-AS1 | H1769: lincRNA | I1769: MAPKAPK5 antisense RNA 1 [Source:HGNC Symbol;Acc:HGNC:24091]
A1770: ENSG00000234616 | B1770: 597.3634 | C1770: 469.4598 | D1770: 0.34761 | E1770: 0.00030897 | F1770: 0.0036306 | G1770: JRK | H1770: protein_coding | I1770: Jrk helix-turn-helix protein [Source:HGNC Symbol;Acc:HGNC:6199]
A1771: ENSG00000234694 | B1771: 15.745084 | C1771: 3.1350361 | D1771: 2.3283 | E1771: 0.0031566 | F1771: 0.027586 | G1771: RP1-92O14.3 | H1771: antisense | I1771: -
A1772: ENSG00000235109 | B1772: 1003.0805 | C1772: 606.84177 | D1772: 0.72505 | E1772: 1.06e-09 | F1772: 3.34e-08 | G1772: ZSCAN31 | H1772: protein_coding | I1772: zinc finger and SCAN domain containing 31 [Source:HGNC Symbol;Acc:HGNC:14097]
A1773: ENSG00000235173 | B1773: 353.44495 | C1773: 273.12284 | D1773: 0.37194 | E1773: 0.0023097 | F1773: 0.021165 | G1773: HGH1 | H1773: protein_coding | I1773: HGH1 homolog [Source:HGNC Symbol;Acc:HGNC:24161]
...

Sheet DEGs
A1: Associated Gene Name | B1: Gene_id | C1: readcount_ND2 | D1: readcount_LUC | E1: log2FoldChange | F1: pval | G1: padj | H1: Associated Gene Name | I1: gene_biotype | J1: Description
A2: FUCA2 | B2: ENSG00000001036 | C2: 1504.7666 | D2: 1260.5838 | E2: 0.25545 | F2: 6.72e-05 | G2: 0.00093032 | H2: FUCA2 | I2: protein_coding | J2: fucosidase, alpha-L- 2, plasma [Source:HGNC Symbol;Acc:HGNC:4008]
A3: LAS1L | B3: ENSG00000001497 | C3: 1098.1362 | D3: 902.54002 | E3: 0.28299 | F3: 9.76e-05 | G3: 0.0013007 | H3: LAS1L | I3: protein_coding | J3: LAS1-like, ribosome biogenesis factor [Source:HGNC Symbol;Acc:HGNC:25726]
A4: CFTR | B4: ENSG00000001626 | C4: 27.222571 | D4: 7.8600962 | E4: 1.7922 | F4: 0.0009204 | G4: 0.0095104 | H4: CFTR | I4: protein_coding | J4: cystic fibrosis transmembrane conductance regulator [Source:HGNC Symbol;Acc:HGNC:1884]
A5: MAD1L1 | B5: ENSG00000002822 | C5: 472.85565 | D5: 356.76881 | E5: 0.40641 | F5: 0.00013966 | G5: 0.0017847 | H5: MAD1L1 | I5: protein_coding | J5: MAD1 mitotic arrest deficient-like 1 (yeast) [Source:HGNC Symbol;Acc:HGNC:6762]
A6: M6PR | B6: ENSG00000003056 | C6: 1260.819 | D6: 988.92566 | E6: 0.35043 | F6: 4.69e-07 | G6: 9.88e-06 | H6: M6PR | I6: protein_coding | J6: mannose-6-phosphate receptor (cation dependent) [Source:HGNC Symbol;Acc:HGNC:6752]
A7: HCCS | B7: ENSG00000004961 | C7: 326.42656 | D7: 250.80288 | E7: 0.3802 | F7: 0.0023309 | G7: 0.021339 | H7: HCCS | I7: protein_coding | J7: holocytochrome c synthase [Source:HGNC Symbol;Acc:HGNC:4837]
A8: DVL2 | B8: ENSG00000004975 | C8: 1373.1948 | D8: 953.71034 | E8: 0.52591 | F8: 2.04e-14 | G8: 1.11e-12 | H8: DVL2 | I8: protein_coding | J8: dishevelled segment polarity protein 2 [Source:HGNC Symbol;Acc:HGNC:3086]
A9: UPF1 | B9: ENSG00000005007 | C9: 1799.7394 | D9: 1426.2456 | E9: 0.33557 | F9: 1.23e-06 | G9: 2.41e-05 | H9: UPF1 | I9: protein_coding | J9: UPF1 regulator of nonsense transcripts homolog (yeast) [Source:HGNC Symbol;Acc:HGNC:9962]
A10: DHX33 | B10: ENSG00000005100 | C10: 947.37568 | D10: 759.42326 | E10: 0.31903 | F10: 3.93e-05 | G10: 0.00057389 | H10: DHX33 | I10: protein_coding | J10: DEAH (Asp-Glu-Ala-His) box polypeptide 33 [Source:HGNC Symbol;Acc:HGNC:16718]
A11: SPPL2B | B11: ENSG00000005206 | C11: 341.87996 | D11: 266.02794 | E11: 0.36191 | F11: 0.0030881 | G11: 0.027143 | H11: SPPL2B | I11: protein_coding | J11: signal peptide peptidase like 2B [Source:HGNC Symbol;Acc:HGNC:30627]
A12: COPZ2 | B12: ENSG00000005243 | C12: 200.46041 | D12: 137.99147 | E12: 0.53874 | F12: 0.0024799 | G12: 0.022558 | H12: COPZ2 | I12: protein_coding | J12: coatomer protein complex subunit zeta 2 [Source:HGNC Symbol;Acc:HGNC:19356]
A13: WDR54 | B13: ENSG00000005448 | C13: 712.15101 | D13: 590.54615 | E13: 0.27013 | F13: 0.0053953 | G13: 0.043477 | H13: WDR54 | I13: protein_coding | J13: WD repeat domain 54 [Source:HGNC Symbol;Acc:HGNC:25770]
... A1524: TOP1MT | B1524: ENSG00000184428 | C1524: 368.72882 | D1524: 198.10703 | E1524: 0.89628 | F1524: 3.19e-12 | G1524: 1.37e-10 | H1524: TOP1MT | I1524: protein_coding | J1524: topoisomerase (DNA) I, mitochondrial [Source:HGNC Symbol;Acc:HGNC:29787]
A1525: 44813 | B1525: ENSG00000184640 | C1525: 3676.3576 | D1525: 2710.7296 | E1525: 0.4396 | F1525: 3.55e-19 | G1525: 2.8e-17 | H1525: 44813 | I1525: protein_coding | J1525: septin 9 [Source:HGNC Symbol;Acc:HGNC:7323]
A1526: TMED9 | B1526: ENSG00000184840 | C1526: 2004.7209 | D1526: 1543.1762 | E1526: 0.3775 | F1526: 4.23e-07 | G1526: 9.02e-06 | H1526: TMED9 | I1526: protein_coding | J1526: transmembrane p24 trafficking protein 9 [Source:HGNC Symbol;Acc:HGNC:24878]
A1527: TMEM186 | B1527: ENSG00000184857 | C1527: 197.7861 | D1527: 121.04621 | E1527: 0.70838 | F1527: 2.67e-05 | G1527: 0.00040483 | H1527: TMEM186 | I1527: protein_coding | J1527: transmembrane protein 186 [Source:HGNC Symbol;Acc:HGNC:24530]
A1528: BTBD6 | B1528: ENSG00000184887 | C1528: 649.75951 | D1528: 533.3357 | E1528: 0.28486 | F1528: 0.0017352 | G1528: 0.016579 | H1528: BTBD6 | I1528: protein_coding | J1528: BTB (POZ) domain containing 6 [Source:HGNC Symbol;Acc:HGNC:19897]
A1529: ZFP90 | B1529: ENSG00000184939 | C1529: 209.63183 | D1529: 154.2518 | E1529: 0.44257 | F1529: 0.0040198 | G1529: 0.033791 | H1529: ZFP90 | I1529: protein_coding | J1529: ZFP90 zinc finger protein [Source:HGNC Symbol;Acc:HGNC:23329]
A1530: FAM227A | B1530: ENSG00000184949 | C1530: 52.25027 | D1530: 25.990264 | E1530: 1.0075 | F1530: 0.0032855 | G1530: 0.028511 | H1530: FAM227A | I1530: protein_coding | J1530: family with sequence similarity 227 member A [Source:HGNC Symbol;Acc:HGNC:44197]
A1531: AP3M1 | B1531: ENSG00000185009 | C1531: 589.03785 | D1531: 449.67025 | E1531: 0.38949 | F1531: 4.26e-05 | G1531: 0.00061689 | H1531: AP3M1 | I1531: protein_coding | J1531: adaptor related protein complex 3, mu 1 subunit [Source:HGNC Symbol;Acc:HGNC:569]
A1532: UBOX5 | B1532: ENSG00000185019 | C1532: 145.99705 | D1532: 94.186118 | E1532: 0.63235 | F1532: 0.00091842 | G1532: 0.0094932 | H1532: UBOX5 | I1532: protein_coding | J1532: U-box domain containing 5 [Source:HGNC Symbol;Acc:HGNC:17777]
A1533: CIB1 | B1533: ENSG00000185043 | C1533: 568.44181 | D1533: 450.49507 | E1533: 0.3355 | F1533: 0.00047956 | G1533: 0.0053444 | H1533: CIB1 | I1533: protein_coding | J1533: calcium and integrin binding 1 [Source:HGNC Symbol;Acc:HGNC:16920]
A1534: NELFA | B1534: ENSG00000185049 | C1534: 604.947 | D1534: 435.19459 | E1534: 0.47515 | F1534: 7.9e-07 | G1534: 1.6e-05 | H1534: NELFA | I1534: protein_coding | J1534: negative elongation factor complex member A [Source:HGNC Symbol;Acc:HGNC:12768]
A1535: HSF1 | B1535: ENSG00000185122 | C1535: 1042.8798 | D1535: 822.89405 | E1535: 0.34179 | F1535: 4.7e-06 | G1535: 8.3e-05 | H1535: HSF1 | I1535: protein_coding | J1535: heat shock transcription factor 1 [Source:HGNC Symbol;Acc:HGNC:5224]
A1536: NRBP2 | B1536: ENSG00000185189 | C1536: 182.93428 | D1536: 118.22626 | E1536: 0.62977 | F1536: 0.00025266 | G1536: 0.0030445 | H1536: NRBP2 | I1536: protein_coding | J1536: nuclear receptor binding protein 2 [Source:HGNC Symbol;Acc:HGNC:19339]
A1537: TNFAIP2 | B1537: ENSG00000185215 | C1537: 1154.7306 | D1537: 999.24075 | E1537: 0.20865 | F1537: 0.0032289 | G1537: 0.028124 | H1537: TNFAIP2 | I1537: protein_coding | J1537: TNF alpha induced protein 2 [Source:HGNC Symbol;Acc:HGNC:11895]
... A1761: LINC-PINT | B1761: ENSG00000231721 | C1761: 178.1763 | D1761: 101.27127 | E1761: 0.81508 | F1761: 4.14e-06 | G1761: 7.37e-05 | H1761: LINC-PINT | I1761: antisense | J1761: long intergenic non-protein coding RNA, p53 induced transcript [Source:HGNC Symbol;Acc:HGNC:26885]
A1762: TSPAN19 | B1762: ENSG00000231738 | C1762: 12.399914 | D1762: 0 | E1762: Inf | F1762: 4.34e-05 | G1762: 0.00062761 | H1762: TSPAN19 | I1762: protein_coding | J1762: tetraspanin 19 [Source:HGNC Symbol;Acc:HGNC:31886]
A1763: PIK3CD-AS2 | B1763: ENSG00000231789 | C1763: 122.61003 | D1763: 66.115565 | E1763: 0.89102 | F1763: 0.00018583 | G1763: 0.0023007 | H1763: PIK3CD-AS2 | I1763: antisense | J1763: PIK3CD antisense RNA 2 [Source:HGNC Symbol;Acc:HGNC:51334]
A1764: CTD-2619J13.14 | B1764: ENSG00000232098 | C1764: 235.26658 | D1764: 143.67151 | E1764: 0.71152 | F1764: 3.7e-06 | G1764: 6.67e-05 | H1764: CTD-2619J13.14 | I1764: lincRNA | J1764: -
A1765: LINC00472 | B1765: ENSG00000233237 | C1765: 32.009718 | D1765: 12.040144 | E1765: 1.4107 | F1765: 0.0026628 | G1765: 0.024002 | H1765: LINC00472 | I1765: lincRNA | J1765: long intergenic non-protein coding RNA 472 [Source:HGNC Symbol;Acc:HGNC:21380]
A1766: TRIM26 | B1766: ENSG00000234127 | C1766: 629.68302 | D1766: 435.01941 | E1766: 0.53355 | F1766: 1.88e-06 | G1766: 3.56e-05 | H1766: TRIM26 | I1766: protein_coding | J1766: tripartite motif containing 26 [Source:HGNC Symbol;Acc:HGNC:12962]
A1767: RNASEH1-AS1 | B1767: ENSG00000234171 | C1767: 194.21306 | D1767: 124.40631 | E1767: 0.64258 | F1767: 0.00013523 | G1767: 0.0017355 | H1767: RNASEH1-AS1 | I1767: antisense | J1767: RNASEH1 antisense RNA 1 [Source:HGNC Symbol;Acc:HGNC:49289]
A1768: AC012146.7 | B1768: ENSG00000234327 | C1768: 82.181788 | D1768: 46.615565 | E1768: 0.81801 | F1768: 0.0017343 | G1768: 0.016575 | H1768: AC012146.7 | I1768: processed_transcript | J1768: -
A1769: MAPKAPK5-AS1 | B1769: ENSG00000234608 | C1769: 248.97358 | D1769: 186.01214 | E1769: 0.4206 | F1769: 0.003307 | G1769: 0.028646 | H1769: MAPKAPK5-AS1 | I1769: lincRNA | J1769: MAPKAPK5 antisense RNA 1 [Source:HGNC Symbol;Acc:HGNC:24091]
A1770: JRK | B1770: ENSG00000234616 | C1770: 597.3634 | D1770: 469.4598 | E1770: 0.34761 | F1770: 0.00030897 | G1770: 0.0036306 | H1770: JRK | I1770: protein_coding | J1770: Jrk helix-turn-helix protein [Source:HGNC Symbol;Acc:HGNC:6199]
A1771: RP1-92O14.3 | B1771: ENSG00000234694 | C1771: 15.745084 | D1771: 3.1350361 | E1771: 2.3283 | F1771: 0.0031566 | G1771: 0.027586 | H1771: RP1-92O14.3 | I1771: antisense | J1771: -
A1772: ZSCAN31 | B1772: ENSG00000235109 | C1772: 1003.0805 | D1772: 606.84177 | E1772: 0.72505 | F1772: 1.06e-09 | G1772: 3.34e-08 | H1772: ZSCAN31 | I1772: protein_coding | J1772: zinc finger and SCAN domain containing 31 [Source:HGNC Symbol;Acc:HGNC:14097]
A1773: HGH1 | B1773: ENSG00000235173 | C1773: 353.44495 | D1773: 273.12284 | E1773: 0.37194 | F1773: 0.0023097 | G1773: 0.021165 | H1773: HGH1 | I1773: protein_coding | J1773: HGH1 homolog [Source:HGNC Symbol;Acc:HGNC:24161]
...

Sheet corplot
A1: gene | B1: readcount_ND2 | C1: readcount_LUC | G1: gene | H1: readcount_ND2 | I1: readcount_LUC
A2: DVL1 | B2: =VLOOKUP(A2,DEGs!$A$1:$I$3761,3,FALSE) -> 1243.3749 | C2: =VLOOKUP(A2,DEGs!$A$1:$I$3761,4,FALSE) -> 996.27602 | G2: DVL1 | H2: =VLOOKUP(G2,DEGs!$A$1:$I$3761,3,FALSE) -> 1243.3749 | I2: =VLOOKUP(G2,DEGs!$A$1:$I$3761,4,FALSE) -> 996.27602
A3: DVL2 | B3: =VLOOKUP(A3,DEGs!$A$1:$I$3761,3,FALSE) -> 1373.1948 | C3: =VLOOKUP(A3,DEGs!$A$1:$I$3761,4,FALSE) -> 953.71034 | G3: DVL2 | H3: =VLOOKUP(G3,DEGs!$A$1:$I$3761,3,FALSE) -> 1373.1948 | I3: =VLOOKUP(G3,DEGs!$A$1:$I$3761,4,FALSE) -> 953.71034
A4: DVL3 | B4: =VLOOKUP(A4,DEGs!$A$1:$I$3761,3,FALSE) -> 935.49531 | C4: =VLOOKUP(A4,DEGs!$A$1:$I$3761,4,FALSE) -> 777.63858 | G4: DVL3 | H4: =VLOOKUP(G4,DEGs!$A$1:$I$3761,3,FALSE) -> 935.49531 | I4: =VLOOKUP(G4,DEGs!$A$1:$I$3761,4,FALSE) -> 777.63858
A5: JAG1 | B5: =VLOOKUP(A5,DEGs!$A$1:$I$3761,3,FALSE) -> 1395.4315 | C5: =VLOOKUP(A5,DEGs!$A$1:$I$3761,4,FALSE) -> 1991.2066 | G5: JAG1 | H5: =VLOOKUP(G5,DEGs!$A$1:$I$3761,3,FALSE) -> 1395.4315 | I5: =VLOOKUP(G5,DEGs!$A$1:$I$3761,4,FALSE) -> 1991.2066
A6: KAT2A | B6: =VLOOKUP(A6,DEGs!$A$1:$I$3761,3,FALSE) -> 716.65743 | C6: =VLOOKUP(A6,DEGs!$A$1:$I$3761,4,FALSE) -> 567.7262 | G6: KAT2A | H6: =VLOOKUP(G6,DEGs!$A$1:$I$3761,3,FALSE) -> 716.65743 | I6: =VLOOKUP(G6,DEGs!$A$1:$I$3761,4,FALSE) -> 567.7262
A7: HES1 | B7: =VLOOKUP(A7,DEGs!$A$1:$I$3761,3,FALSE) -> 27.625449 | C7: =VLOOKUP(A7,DEGs!$A$1:$I$3761,4,FALSE) -> 82.650841 | G7: HES1 | H7: =VLOOKUP(G7,DEGs!$A$1:$I$3761,3,FALSE) -> 27.625449 | I7: =VLOOKUP(G7,DEGs!$A$1:$I$3761,4,FALSE) -> 82.650841
A8: RBPJ | B8: =VLOOKUP(A8,DEGs!$A$1:$I$3761,3,FALSE) -> 2878.3624 | C8: =VLOOKUP(A8,DEGs!$A$1:$I$3761,4,FALSE) -> 3456.7076 | G8: RBPJ | H8: =VLOOKUP(G8,DEGs!$A$1:$I$3761,3,FALSE) -> 2878.3624 | I8: =VLOOKUP(G8,DEGs!$A$1:$I$3761,4,FALSE) -> 3456.7076
A9: LFNG | B9: =VLOOKUP(A9,DEGs!$A$1:$I$3761,3,FALSE) -> 50.522086 | C9: =VLOOKUP(A9,DEGs!$A$1:$I$3761,4,FALSE) -> 124.35643 | G9: LFNG | H9: =VLOOKUP(G9,DEGs!$A$1:$I$3761,3,FALSE) -> 50.522086 | I9: =VLOOKUP(G9,DEGs!$A$1:$I$3761,4,FALSE) -> 124.35643
A10: MAML1 | B10: =VLOOKUP(A10,DEGs!$A$1:$I$3761,3,FALSE) -> 915.31857 | C10: =VLOOKUP(A10,DEGs!$A$1:$I$3761,4,FALSE) -> 606.53642 | G10: MAML1 | H10: =VLOOKUP(G10,DEGs!$A$1:$I$3761,3,FALSE) -> 915.31857 | I10: =VLOOKUP(G10,DEGs!$A$1:$I$3761,4,FALSE) -> 606.53642
A11: DTX4 | B11: =VLOOKUP(A11,DEGs!$A$1:$I$3761,3,FALSE) -> 131.57727 | C11: =VLOOKUP(A11,DEGs!$A$1:$I$3761,4,FALSE) -> 201.5024 | G11: DTX4 | H11: =VLOOKUP(G11,DEGs!$A$1:$I$3761,3,FALSE) -> 131.57727 | I11: =VLOOKUP(G11,DEGs!$A$1:$I$3761,4,FALSE) -> 201.5024
A12: NCSTN | B12: =VLOOKUP(A12,DEGs!$A$1:$I$3761,3,FALSE) -> 1111.7976 | C12: =VLOOKUP(A12,DEGs!$A$1:$I$3761,4,FALSE) -> 847.79429 | G12: NCSTN | H12: =VLOOKUP(G12,DEGs!$A$1:$I$3761,3,FALSE) -> 1111.7976 | I12: =VLOOKUP(G12,DEGs!$A$1:$I$3761,4,FALSE) -> 847.79429
A13: DLL1 | B13: =VLOOKUP(A13,DEGs!$A$1:$I$3761,3,FALSE) -> 11.419151 | C13: =VLOOKUP(A13,DEGs!$A$1:$I$3761,4,FALSE) -> 32.6253 | G13: DLL1 | H13: =VLOOKUP(G13,DEGs!$A$1:$I$3761,3,FALSE) -> 11.419151 | I13: =VLOOKUP(G13,DEGs!$A$1:$I$3761,4,FALSE) -> 32.6253
... A59: EIF2B1 | B59: =VLOOKUP(A59,DEGs!$A$1:$I$3761,3,FALSE) -> 1135.8682 | C59: =VLOOKUP(A59,DEGs!$A$1:$I$3761,4,FALSE) -> 853.6848 | G59: RASSF2 | H59: =VLOOKUP(G59,DEGs!$A$1:$I$3761,3,FALSE) -> 21.886705 | I59: =VLOOKUP(G59,DEGs!$A$1:$I$3761,4,FALSE) -> 56.430649
A60: EIF4EBP2 | B60: =VLOOKUP(A60,DEGs!$A$1:$I$3761,3,FALSE) -> 975.87069 | C60: =VLOOKUP(A60,DEGs!$A$1:$I$3761,4,FALSE) -> 1200.8283
A61: EREG | B61: =VLOOKUP(A61,DEGs!$A$1:$I$3761,3,FALSE) -> 463.64959 | C61: =VLOOKUP(A61,DEGs!$A$1:$I$3761,4,FALSE) -> 1445.8015
A62: FBN1 | B62: =VLOOKUP(A62,DEGs!$A$1:$I$3761,3,FALSE) -> 2548.5287 | C62: =VLOOKUP(A62,DEGs!$A$1:$I$3761,4,FALSE) -> 1937.9012
A63: FER | B63: =VLOOKUP(A63,DEGs!$A$1:$I$3761,3,FALSE) -> 338.99601 | C63: =VLOOKUP(A63,DEGs!$A$1:$I$3761,4,FALSE) -> 462.30529
A64: FOXO3 | B64: =VLOOKUP(A64,DEGs!$A$1:$I$3761,3,FALSE) -> 335.94252 | C64: =VLOOKUP(A64,DEGs!$A$1:$I$3761,4,FALSE) -> 643.70186
A65: FYN | B65: =VLOOKUP(A65,DEGs!$A$1:$I$3761,3,FALSE) -> 8.073981 | C65: =VLOOKUP(A65,DEGs!$A$1:$I$3761,4,FALSE) -> 30.535276
A66: GJA1 | B66: =VLOOKUP(A66,DEGs!$A$1:$I$3761,3,FALSE) -> 1979.0861 | C66: =VLOOKUP(A66,DEGs!$A$1:$I$3761,4,FALSE) -> 1521.6665
A67: GNAI1 | B67: =VLOOKUP(A67,DEGs!$A$1:$I$3761,3,FALSE) -> 779.52109 | C67: =VLOOKUP(A67,DEGs!$A$1:$I$3761,4,FALSE) -> 1671.2139
A68: GNAI2 | B68: =VLOOKUP(A68,DEGs!$A$1:$I$3761,3,FALSE) -> 5022.4811 | C68: =VLOOKUP(A68,DEGs!$A$1:$I$3761,4,FALSE) -> 4353.7379
A69: HSF1 | B69: =VLOOKUP(A69,DEGs!$A$1:$I$3761,3,FALSE) -> 1042.8798 | C69: =VLOOKUP(A69,DEGs!$A$1:$I$3761,4,FALSE) -> 822.89405
A70: ICAM1 | B70: =VLOOKUP(A70,DEGs!$A$1:$I$3761,3,FALSE) -> 14.705984 | C70: =VLOOKUP(A70,DEGs!$A$1:$I$3761,4,FALSE) -> 33.985397
A71: IGF1R | B71: =VLOOKUP(A71,DEGs!$A$1:$I$3761,3,FALSE) -> 1203.2274 | C71: =VLOOKUP(A71,DEGs!$A$1:$I$3761,4,FALSE) -> 902.26022
... A252: DVL3 | B252: =VLOOKUP(A252,DEGs!$A$1:$I$3761,3,FALSE) -> 935.49531 | C252: =VLOOKUP(A252,DEGs!$A$1:$I$3761,4,FALSE) -> 777.63858
